INFO:root:12:25:18 - TGTG: 200(OK). Items: 81
INFO:root:12:25:19 - Foodsi: 200(OK). Items with stock: 15 All items: 15
ERROR:root:Traceback (most recent call last):
  File "watch.py", line 50, in watch
    tgtg_handler.handle()
  File "/home/aleksandra/pythonProject/TooGoodToGoBundle/Handler/TgtgHandler.py", line 18, in handle
    coordinates = self._coordinates_manager.get_coordinates()
  File "/home/aleksandra/pythonProject/Core/Utils/CoordinatesManager.py", line 18, in get_coordinates
    self.set_coordinates()
  File "/home/aleksandra/pythonProject/Core/Utils/CoordinatesManager.py", line 22, in set_coordinates
    lat = input("Type your latitude: ")
KeyboardInterrupt

INFO:root:13:41:32 - TGTG: 200(OK). Items: 81
INFO:root:13:41:33 - Foodsi: 200(OK). Items with stock: 15 All items: 15
INFO:root:13:41:46 - TGTG: 200(OK). Items: 81
INFO:root:13:41:47 - Foodsi: 200(OK). Items with stock: 15 All items: 15
INFO:root:13:42:03 - TGTG: 200(OK). Items: 81
INFO:root:13:42:04 - Foodsi: 200(OK). Items with stock: 15 All items: 15
INFO:root:13:42:28 - TGTG: 200(OK). Items: 81
INFO:root:13:42:30 - Foodsi: 200(OK). Items with stock: 15 All items: 15
INFO:root:13:43:16 - TGTG: 200(OK). Items: 81
INFO:root:13:43:18 - Foodsi: 200(OK). Items with stock: 15 All items: 15
INFO:root:13:43:32 - TGTG: 200(OK). Items: 81
INFO:root:13:43:33 - Foodsi: 200(OK). Items with stock: 15 All items: 15
INFO:root:13:43:49 - TGTG: 200(OK). Items: 81
INFO:root:13:43:50 - Foodsi: 200(OK). Items with stock: 15 All items: 15
INFO:root:13:46:27 - TGTG: 200(OK). Items: 81
ERROR:root:Traceback (most recent call last):
  File "watch.py", line 60, in watch
    foodsi_handler.handle()
  File "/home/aleksandra/pythonProject/FoodsiBundle/Handler/FoodsiHandler.py", line 31, in handle
    item_data = fetch_items()
  File "/home/aleksandra/pythonProject/FoodsiBundle/Api/FoodsiApi.py", line 41, in fetch_items
    foodsi_api = requests.post(
  File "/home/aleksandra/.local/lib/python3.8/site-packages/requests/api.py", line 115, in post
    return request("post", url, data=data, json=json, **kwargs)
  File "/home/aleksandra/.local/lib/python3.8/site-packages/requests/api.py", line 59, in request
    return session.request(method=method, url=url, **kwargs)
  File "/home/aleksandra/.local/lib/python3.8/site-packages/requests/sessions.py", line 587, in request
    resp = self.send(prep, **send_kwargs)
  File "/home/aleksandra/.local/lib/python3.8/site-packages/requests/sessions.py", line 701, in send
    r = adapter.send(request, **kwargs)
  File "/home/aleksandra/.local/lib/python3.8/site-packages/requests/adapters.py", line 487, in send
    resp = conn.urlopen(
  File "/home/aleksandra/.local/lib/python3.8/site-packages/urllib3/connectionpool.py", line 703, in urlopen
    httplib_response = self._make_request(
  File "/home/aleksandra/.local/lib/python3.8/site-packages/urllib3/connectionpool.py", line 386, in _make_request
    self._validate_conn(conn)
  File "/home/aleksandra/.local/lib/python3.8/site-packages/urllib3/connectionpool.py", line 1042, in _validate_conn
    conn.connect()
  File "/home/aleksandra/.local/lib/python3.8/site-packages/urllib3/connection.py", line 363, in connect
    self.sock = conn = self._new_conn()
  File "/home/aleksandra/.local/lib/python3.8/site-packages/urllib3/connection.py", line 174, in _new_conn
    conn = connection.create_connection(
  File "/home/aleksandra/.local/lib/python3.8/site-packages/urllib3/util/connection.py", line 85, in create_connection
    sock.connect(sa)
KeyboardInterrupt

INFO:root:13:46:42 - TGTG: 200(OK). Items: 81
INFO:root:13:46:44 - Foodsi: 200(OK). Items with stock: 15 All items: 15
INFO:root:13:49:10 - TGTG: 200(OK). Items: 81
INFO:root:13:49:11 - Foodsi: 200(OK). Items with stock: 15 All items: 15
INFO:root:13:49:39 - TGTG: 200(OK). Items: 81
INFO:root:13:49:40 - Foodsi: 200(OK). Items with stock: 15 All items: 15
INFO:root:13:49:54 - TGTG: 200(OK). Items: 81
INFO:root:13:49:55 - Foodsi: 200(OK). Items with stock: 15 All items: 15
INFO:root:13:50:11 - TGTG: 200(OK). Items: 81
ERROR:root:Traceback (most recent call last):
  File "watch.py", line 62, in watch
    foodsi_handler.handle()
  File "/home/aleksandra/pythonProject/FoodsiBundle/Handler/FoodsiHandler.py", line 31, in handle
    item_data = fetch_items()
  File "/home/aleksandra/pythonProject/FoodsiBundle/Api/FoodsiApi.py", line 41, in fetch_items
    foodsi_api = requests.post(
  File "/home/aleksandra/.local/lib/python3.8/site-packages/requests/api.py", line 115, in post
    return request("post", url, data=data, json=json, **kwargs)
  File "/home/aleksandra/.local/lib/python3.8/site-packages/requests/api.py", line 59, in request
    return session.request(method=method, url=url, **kwargs)
  File "/home/aleksandra/.local/lib/python3.8/site-packages/requests/sessions.py", line 587, in request
    resp = self.send(prep, **send_kwargs)
  File "/home/aleksandra/.local/lib/python3.8/site-packages/requests/sessions.py", line 701, in send
    r = adapter.send(request, **kwargs)
  File "/home/aleksandra/.local/lib/python3.8/site-packages/requests/adapters.py", line 487, in send
    resp = conn.urlopen(
  File "/home/aleksandra/.local/lib/python3.8/site-packages/urllib3/connectionpool.py", line 703, in urlopen
    httplib_response = self._make_request(
  File "/home/aleksandra/.local/lib/python3.8/site-packages/urllib3/connectionpool.py", line 449, in _make_request
    six.raise_from(e, None)
  File "<string>", line 3, in raise_from
  File "/home/aleksandra/.local/lib/python3.8/site-packages/urllib3/connectionpool.py", line 444, in _make_request
    httplib_response = conn.getresponse()
  File "/usr/lib/python3.8/http/client.py", line 1348, in getresponse
    response.begin()
  File "/usr/lib/python3.8/http/client.py", line 316, in begin
    version, status, reason = self._read_status()
  File "/usr/lib/python3.8/http/client.py", line 277, in _read_status
    line = str(self.fp.readline(_MAXLINE + 1), "iso-8859-1")
  File "/usr/lib/python3.8/socket.py", line 669, in readinto
    return self._sock.recv_into(b)
  File "/usr/lib/python3.8/ssl.py", line 1241, in recv_into
    return self.read(nbytes, buffer)
  File "/usr/lib/python3.8/ssl.py", line 1099, in read
    return self._sslobj.read(len, buffer)
KeyboardInterrupt

ERROR:root:Traceback (most recent call last):
  File "watch.py", line 55, in watch
    response = requests.get('https://api.telegram.org/bot' + bot_token + '/getUpdates?limit=1&offset=' + lastUpdateID + '&timeout=15')
NameError: name 'lastUpdateID' is not defined

ERROR:root:Traceback (most recent call last):
  File "watch.py", line 55, in watch
    response = requests.get('https://api.telegram.org/bot' + bot_token + '/getUpdates?limit=1&offset=' + offset + '&timeout=15')
TypeError: can only concatenate str (not "int") to str

INFO:root:13:52:38 - TGTG: 200(OK). Items: 81
INFO:root:13:52:39 - Foodsi: 200(OK). Items with stock: 15 All items: 15
INFO:root:13:52:53 - TGTG: 200(OK). Items: 81
INFO:root:13:52:55 - Foodsi: 200(OK). Items with stock: 15 All items: 15
INFO:root:13:54:00 - TGTG: 200(OK). Items: 81
INFO:root:13:54:02 - Foodsi: 200(OK). Items with stock: 15 All items: 15
INFO:root:13:54:16 - TGTG: 200(OK). Items: 81
INFO:root:13:54:17 - Foodsi: 200(OK). Items with stock: 15 All items: 15
INFO:root:18:36:08 - TGTG: 200(OK). Items: 79
INFO:root:18:36:10 - Foodsi: 200(OK). Items with stock: 0 All items: 15
ERROR:root:Traceback (most recent call last):
  File "watch.py", line 52, in watch
    raise Exception('dsads')
Exception: dsads

INFO:root:18:36:22 - TGTG: 200(OK). Items: 79
INFO:root:18:36:23 - Foodsi: 200(OK). Items with stock: 0 All items: 15
ERROR:root:Traceback (most recent call last):
  File "watch.py", line 52, in watch
    raise Exception('dsads')
Exception: dsads

ERROR:root:Traceback (most recent call last):
  File "watch.py", line 53, in watch
    tgtg_handler.handle()
  File "/home/aleksandra/pythonProject/TooGoodToGoBundle/Handler/TgtgHandler.py", line 21, in handle
    StockService.compare(self._stock, item_data)
  File "/home/aleksandra/pythonProject/TooGoodToGoBundle/Service/StockService.py", line 22, in compare
    TelegramApi.send(get_item_message(item, new_stock))
  File "/home/aleksandra/pythonProject/TelegramBundle/Api/TelegramApi.py", line 22, in send
    requests.get(send_text)
  File "/home/aleksandra/.local/lib/python3.8/site-packages/requests/api.py", line 73, in get
    return request("get", url, params=params, **kwargs)
  File "/home/aleksandra/.local/lib/python3.8/site-packages/requests/api.py", line 59, in request
    return session.request(method=method, url=url, **kwargs)
  File "/home/aleksandra/.local/lib/python3.8/site-packages/requests/sessions.py", line 587, in request
    resp = self.send(prep, **send_kwargs)
  File "/home/aleksandra/.local/lib/python3.8/site-packages/requests/sessions.py", line 701, in send
    r = adapter.send(request, **kwargs)
  File "/home/aleksandra/.local/lib/python3.8/site-packages/requests/adapters.py", line 487, in send
    resp = conn.urlopen(
  File "/home/aleksandra/.local/lib/python3.8/site-packages/urllib3/connectionpool.py", line 703, in urlopen
    httplib_response = self._make_request(
  File "/home/aleksandra/.local/lib/python3.8/site-packages/urllib3/connectionpool.py", line 449, in _make_request
    six.raise_from(e, None)
  File "<string>", line 3, in raise_from
  File "/home/aleksandra/.local/lib/python3.8/site-packages/urllib3/connectionpool.py", line 444, in _make_request
    httplib_response = conn.getresponse()
  File "/usr/lib/python3.8/http/client.py", line 1348, in getresponse
    response.begin()
  File "/usr/lib/python3.8/http/client.py", line 316, in begin
    version, status, reason = self._read_status()
  File "/usr/lib/python3.8/http/client.py", line 277, in _read_status
    line = str(self.fp.readline(_MAXLINE + 1), "iso-8859-1")
  File "/usr/lib/python3.8/socket.py", line 669, in readinto
    return self._sock.recv_into(b)
  File "/usr/lib/python3.8/ssl.py", line 1241, in recv_into
    return self.read(nbytes, buffer)
  File "/usr/lib/python3.8/ssl.py", line 1099, in read
    return self._sslobj.read(len, buffer)
KeyboardInterrupt

INFO:root:2023-06-07 18:43:34.045098 - TGTG: 200(OK). Items: 79
INFO:root:18:43:35 - Foodsi: 200(OK). Items with stock: 0 All items: 15
ERROR:root:Traceback (most recent call last):
  File "watch.py", line 54, in watch
    raise Exception('dsads')
Exception: dsads

INFO:root:2023-06-07 18:43:59.722292 - TGTG: 200(OK). Items: 79
ERROR:root:Traceback (most recent call last):
  File "watch.py", line 53, in watch
    foodsi_handler.handle()
  File "/home/aleksandra/pythonProject/FoodsiBundle/Handler/FoodsiHandler.py", line 31, in handle
    item_data = fetch_items()
  File "/home/aleksandra/pythonProject/FoodsiBundle/Api/FoodsiApi.py", line 41, in fetch_items
    foodsi_api = requests.post(
  File "/home/aleksandra/.local/lib/python3.8/site-packages/requests/api.py", line 115, in post
    return request("post", url, data=data, json=json, **kwargs)
  File "/home/aleksandra/.local/lib/python3.8/site-packages/requests/api.py", line 59, in request
    return session.request(method=method, url=url, **kwargs)
  File "/home/aleksandra/.local/lib/python3.8/site-packages/requests/sessions.py", line 587, in request
    resp = self.send(prep, **send_kwargs)
  File "/home/aleksandra/.local/lib/python3.8/site-packages/requests/sessions.py", line 701, in send
    r = adapter.send(request, **kwargs)
  File "/home/aleksandra/.local/lib/python3.8/site-packages/requests/adapters.py", line 487, in send
    resp = conn.urlopen(
  File "/home/aleksandra/.local/lib/python3.8/site-packages/urllib3/connectionpool.py", line 703, in urlopen
    httplib_response = self._make_request(
  File "/home/aleksandra/.local/lib/python3.8/site-packages/urllib3/connectionpool.py", line 449, in _make_request
    six.raise_from(e, None)
  File "<string>", line 3, in raise_from
  File "/home/aleksandra/.local/lib/python3.8/site-packages/urllib3/connectionpool.py", line 444, in _make_request
    httplib_response = conn.getresponse()
  File "/usr/lib/python3.8/http/client.py", line 1348, in getresponse
    response.begin()
  File "/usr/lib/python3.8/http/client.py", line 316, in begin
    version, status, reason = self._read_status()
  File "/usr/lib/python3.8/http/client.py", line 277, in _read_status
    line = str(self.fp.readline(_MAXLINE + 1), "iso-8859-1")
  File "/usr/lib/python3.8/socket.py", line 669, in readinto
    return self._sock.recv_into(b)
  File "/usr/lib/python3.8/ssl.py", line 1241, in recv_into
    return self.read(nbytes, buffer)
  File "/usr/lib/python3.8/ssl.py", line 1099, in read
    return self._sslobj.read(len, buffer)
KeyboardInterrupt

INFO:root:07/06/2023 18:45:18 - TGTG: 200(OK). Items: 79
INFO:root:07/06/2023 18:45:19 - Foodsi: 200(OK). Items with stock: 0 All items: 15
ERROR:root:Traceback (most recent call last):
  File "watch.py", line 54, in watch
    raise Exception('dsads')
Exception: dsads

INFO:root:07/06/2023 18:45:36 - TGTG: 200(OK). Items: 79
INFO:root:07/06/2023 18:45:37 - Foodsi: 200(OK). Items with stock: 0 All items: 15
ERROR:root:Traceback (most recent call last):
  File "watch.py", line 54, in watch
    raise Exception('dsads')
Exception: dsads

INFO:root:07/06/2023 18:45:38 - TGTG: 200(OK). Items: 79
INFO:root:07/06/2023 18:45:40 - Foodsi: 200(OK). Items with stock: 0 All items: 15
ERROR:root:Traceback (most recent call last):
  File "watch.py", line 54, in watch
    raise Exception('dsads')
Exception: dsads

During handling of the above exception, another exception occurred:

Traceback (most recent call last):
  File "watch.py", line 54, in watch
    raise Exception('dsads')
Exception: dsads

ERROR:root:Traceback (most recent call last):
  File "watch.py", line 52, in watch
    tgtg_handler.handle()
  File "/home/aleksandra/pythonProject/TooGoodToGoBundle/Handler/TgtgHandler.py", line 20, in handle
    item_data = TgtgAPI.fetch_items(client, coordinates["latitude"], coordinates["longitude"], coordinates["radius"])
  File "/home/aleksandra/pythonProject/TooGoodToGoBundle/Api/TgtgAPI.py", line 59, in fetch_items
    api_response = client.get_items(
  File "/home/aleksandra/.local/lib/python3.8/site-packages/tgtg/__init__.py", line 243, in get_items
    self.login()
  File "/home/aleksandra/.local/lib/python3.8/site-packages/tgtg/__init__.py", line 152, in login
    self._refresh_token()
  File "/home/aleksandra/.local/lib/python3.8/site-packages/tgtg/__init__.py", line 125, in _refresh_token
    response = self.session.post(
  File "/home/aleksandra/.local/lib/python3.8/site-packages/requests/sessions.py", line 635, in post
    return self.request("POST", url, data=data, json=json, **kwargs)
  File "/home/aleksandra/.local/lib/python3.8/site-packages/requests/sessions.py", line 587, in request
    resp = self.send(prep, **send_kwargs)
  File "/home/aleksandra/.local/lib/python3.8/site-packages/requests/sessions.py", line 701, in send
    r = adapter.send(request, **kwargs)
  File "/home/aleksandra/.local/lib/python3.8/site-packages/requests/adapters.py", line 487, in send
    resp = conn.urlopen(
  File "/home/aleksandra/.local/lib/python3.8/site-packages/urllib3/connectionpool.py", line 703, in urlopen
    httplib_response = self._make_request(
  File "/home/aleksandra/.local/lib/python3.8/site-packages/urllib3/connectionpool.py", line 449, in _make_request
    six.raise_from(e, None)
  File "<string>", line 3, in raise_from
  File "/home/aleksandra/.local/lib/python3.8/site-packages/urllib3/connectionpool.py", line 444, in _make_request
    httplib_response = conn.getresponse()
  File "/usr/lib/python3.8/http/client.py", line 1348, in getresponse
    response.begin()
  File "/usr/lib/python3.8/http/client.py", line 316, in begin
    version, status, reason = self._read_status()
  File "/usr/lib/python3.8/http/client.py", line 277, in _read_status
    line = str(self.fp.readline(_MAXLINE + 1), "iso-8859-1")
  File "/usr/lib/python3.8/socket.py", line 669, in readinto
    return self._sock.recv_into(b)
  File "/usr/lib/python3.8/ssl.py", line 1241, in recv_into
    return self.read(nbytes, buffer)
  File "/usr/lib/python3.8/ssl.py", line 1099, in read
    return self._sslobj.read(len, buffer)
KeyboardInterrupt

INFO:root:07/06/2023 18:45:42 - TGTG: 200(OK). Items: 79
INFO:root:07/06/2023 18:45:44 - Foodsi: 200(OK). Items with stock: 0 All items: 15
INFO:root:07/06/2023 18:47:58 - TGTG: 200(OK). Items: 79
INFO:root:07/06/2023 18:47:59 - Foodsi: 200(OK). Items with stock: 0 All items: 15
INFO:root:07/06/2023 18:48:46 - TGTG: 200(OK). Items: 79
INFO:root:07/06/2023 18:48:47 - Foodsi: 200(OK). Items with stock: 0 All items: 15
INFO:root:07/06/2023 18:49:05 - TGTG: 200(OK). Items: 79
INFO:root:07/06/2023 18:49:06 - Foodsi: 200(OK). Items with stock: 0 All items: 15
INFO:root:07/06/2023 18:49:19 - TGTG: 200(OK). Items: 79
INFO:root:07/06/2023 18:49:21 - Foodsi: 200(OK). Items with stock: 0 All items: 15
ERROR:root:Traceback (most recent call last):
  File "watch.py", line 55, in watch
    raise Exception('dsads')
Exception: dsads

INFO:root:07/06/2023 18:49:21 - TGTG: 200(OK). Items: 79
INFO:root:07/06/2023 18:49:22 - Foodsi: 200(OK). Items with stock: 0 All items: 15
ERROR:root:Traceback (most recent call last):
  File "watch.py", line 55, in watch
    raise Exception('dsads')
Exception: dsads

During handling of the above exception, another exception occurred:

Traceback (most recent call last):
  File "watch.py", line 55, in watch
    raise Exception('dsads')
Exception: dsads

INFO:root:07/06/2023 18:49:23 - TGTG: 200(OK). Items: 79
INFO:root:07/06/2023 18:49:24 - Foodsi: 200(OK). Items with stock: 0 All items: 15
ERROR:root:Traceback (most recent call last):
  File "watch.py", line 55, in watch
    raise Exception('dsads')
Exception: dsads

During handling of the above exception, another exception occurred:

Traceback (most recent call last):
  File "watch.py", line 55, in watch
    raise Exception('dsads')
Exception: dsads

During handling of the above exception, another exception occurred:

Traceback (most recent call last):
  File "watch.py", line 55, in watch
    raise Exception('dsads')
Exception: dsads

INFO:root:07/06/2023 18:49:25 - TGTG: 200(OK). Items: 79
INFO:root:07/06/2023 18:49:26 - Foodsi: 200(OK). Items with stock: 0 All items: 15
ERROR:root:Traceback (most recent call last):
  File "watch.py", line 55, in watch
    raise Exception('dsads')
Exception: dsads

During handling of the above exception, another exception occurred:

Traceback (most recent call last):
  File "watch.py", line 55, in watch
    raise Exception('dsads')
Exception: dsads

During handling of the above exception, another exception occurred:

Traceback (most recent call last):
  File "watch.py", line 55, in watch
    raise Exception('dsads')
Exception: dsads

During handling of the above exception, another exception occurred:

Traceback (most recent call last):
  File "watch.py", line 55, in watch
    raise Exception('dsads')
Exception: dsads

INFO:root:07/06/2023 18:49:27 - TGTG: 200(OK). Items: 79
INFO:root:07/06/2023 18:49:28 - Foodsi: 200(OK). Items with stock: 0 All items: 15
ERROR:root:Traceback (most recent call last):
  File "watch.py", line 55, in watch
    raise Exception('dsads')
Exception: dsads

During handling of the above exception, another exception occurred:

Traceback (most recent call last):
  File "watch.py", line 55, in watch
    raise Exception('dsads')
Exception: dsads

During handling of the above exception, another exception occurred:

Traceback (most recent call last):
  File "watch.py", line 55, in watch
    raise Exception('dsads')
Exception: dsads

During handling of the above exception, another exception occurred:

Traceback (most recent call last):
  File "watch.py", line 55, in watch
    raise Exception('dsads')
Exception: dsads

During handling of the above exception, another exception occurred:

Traceback (most recent call last):
  File "watch.py", line 55, in watch
    raise Exception('dsads')
Exception: dsads

INFO:root:07/06/2023 18:49:29 - TGTG: 200(OK). Items: 79
INFO:root:07/06/2023 18:49:31 - Foodsi: 200(OK). Items with stock: 0 All items: 15
ERROR:root:Traceback (most recent call last):
  File "watch.py", line 55, in watch
    raise Exception('dsads')
Exception: dsads

During handling of the above exception, another exception occurred:

Traceback (most recent call last):
  File "watch.py", line 55, in watch
    raise Exception('dsads')
Exception: dsads

During handling of the above exception, another exception occurred:

Traceback (most recent call last):
  File "watch.py", line 55, in watch
    raise Exception('dsads')
Exception: dsads

During handling of the above exception, another exception occurred:

Traceback (most recent call last):
  File "watch.py", line 55, in watch
    raise Exception('dsads')
Exception: dsads

During handling of the above exception, another exception occurred:

Traceback (most recent call last):
  File "watch.py", line 55, in watch
    raise Exception('dsads')
Exception: dsads

During handling of the above exception, another exception occurred:

Traceback (most recent call last):
  File "watch.py", line 55, in watch
    raise Exception('dsads')
Exception: dsads

INFO:root:07/06/2023 18:49:32 - TGTG: 200(OK). Items: 79
INFO:root:07/06/2023 18:49:33 - Foodsi: 200(OK). Items with stock: 0 All items: 15
ERROR:root:Traceback (most recent call last):
  File "watch.py", line 55, in watch
    raise Exception('dsads')
Exception: dsads

During handling of the above exception, another exception occurred:

Traceback (most recent call last):
  File "watch.py", line 55, in watch
    raise Exception('dsads')
Exception: dsads

During handling of the above exception, another exception occurred:

Traceback (most recent call last):
  File "watch.py", line 55, in watch
    raise Exception('dsads')
Exception: dsads

During handling of the above exception, another exception occurred:

Traceback (most recent call last):
  File "watch.py", line 55, in watch
    raise Exception('dsads')
Exception: dsads

During handling of the above exception, another exception occurred:

Traceback (most recent call last):
  File "watch.py", line 55, in watch
    raise Exception('dsads')
Exception: dsads

During handling of the above exception, another exception occurred:

Traceback (most recent call last):
  File "watch.py", line 55, in watch
    raise Exception('dsads')
Exception: dsads

During handling of the above exception, another exception occurred:

Traceback (most recent call last):
  File "watch.py", line 55, in watch
    raise Exception('dsads')
Exception: dsads

INFO:root:07/06/2023 18:49:47 - TGTG: 200(OK). Items: 79
INFO:root:07/06/2023 18:49:49 - Foodsi: 200(OK). Items with stock: 0 All items: 15
ERROR:root:Traceback (most recent call last):
  File "watch.py", line 55, in watch
    raise Exception('dsads')
Exception: dsads

INFO:root:07/06/2023 18:49:50 - TGTG: 200(OK). Items: 79
INFO:root:07/06/2023 18:49:51 - Foodsi: 200(OK). Items with stock: 0 All items: 15
ERROR:root:Traceback (most recent call last):
  File "watch.py", line 55, in watch
    raise Exception('dsads')
Exception: dsads

During handling of the above exception, another exception occurred:

Traceback (most recent call last):
  File "watch.py", line 55, in watch
    raise Exception('dsads')
Exception: dsads

INFO:root:07/06/2023 18:50:38 - TGTG: 200(OK). Items: 79
INFO:root:07/06/2023 18:50:39 - Foodsi: 200(OK). Items with stock: 0 All items: 15
ERROR:root:Traceback (most recent call last):
  File "watch.py", line 55, in watch
    raise Exception('dsads')
Exception: dsads

INFO:root:07/06/2023 18:50:40 - TGTG: 200(OK). Items: 79
INFO:root:07/06/2023 18:50:41 - Foodsi: 200(OK). Items with stock: 0 All items: 15
ERROR:root:Traceback (most recent call last):
  File "watch.py", line 55, in watch
    raise Exception('dsads')
Exception: dsads

During handling of the above exception, another exception occurred:

Traceback (most recent call last):
  File "watch.py", line 55, in watch
    raise Exception('dsads')
Exception: dsads

INFO:root:07/06/2023 18:50:42 - TGTG: 200(OK). Items: 79
INFO:root:07/06/2023 18:50:43 - Foodsi: 200(OK). Items with stock: 0 All items: 15
ERROR:root:Traceback (most recent call last):
  File "watch.py", line 55, in watch
    raise Exception('dsads')
Exception: dsads

During handling of the above exception, another exception occurred:

Traceback (most recent call last):
  File "watch.py", line 55, in watch
    raise Exception('dsads')
Exception: dsads

During handling of the above exception, another exception occurred:

Traceback (most recent call last):
  File "watch.py", line 55, in watch
    raise Exception('dsads')
Exception: dsads

INFO:root:07/06/2023 18:50:44 - TGTG: 200(OK). Items: 79
INFO:root:07/06/2023 18:51:57 - TGTG: 200(OK). Items: 79
INFO:root:07/06/2023 18:51:58 - Foodsi: 200(OK). Items with stock: 0 All items: 15
ERROR:root:Traceback (most recent call last):
  File "watch.py", line 55, in watch
    raise Exception('dsads')
Exception: dsads

INFO:root:07/06/2023 18:51:59 - TGTG: 200(OK). Items: 79
INFO:root:07/06/2023 18:52:01 - Foodsi: 200(OK). Items with stock: 0 All items: 15
ERROR:root:Traceback (most recent call last):
  File "watch.py", line 55, in watch
    raise Exception('dsads')
Exception: dsads

During handling of the above exception, another exception occurred:

Traceback (most recent call last):
  File "watch.py", line 55, in watch
    raise Exception('dsads')
Exception: dsads

INFO:root:07/06/2023 18:52:02 - TGTG: 200(OK). Items: 79
INFO:root:07/06/2023 18:52:03 - Foodsi: 200(OK). Items with stock: 0 All items: 15
ERROR:root:Traceback (most recent call last):
  File "watch.py", line 55, in watch
    raise Exception('dsads')
Exception: dsads

During handling of the above exception, another exception occurred:

Traceback (most recent call last):
  File "watch.py", line 55, in watch
    raise Exception('dsads')
Exception: dsads

During handling of the above exception, another exception occurred:

Traceback (most recent call last):
  File "watch.py", line 55, in watch
    raise Exception('dsads')
Exception: dsads

INFO:root:07/06/2023 18:52:04 - TGTG: 200(OK). Items: 79
INFO:root:07/06/2023 18:52:05 - Foodsi: 200(OK). Items with stock: 0 All items: 15
ERROR:root:Traceback (most recent call last):
  File "watch.py", line 55, in watch
    raise Exception('dsads')
Exception: dsads

During handling of the above exception, another exception occurred:

Traceback (most recent call last):
  File "watch.py", line 55, in watch
    raise Exception('dsads')
Exception: dsads

During handling of the above exception, another exception occurred:

Traceback (most recent call last):
  File "watch.py", line 55, in watch
    raise Exception('dsads')
Exception: dsads

During handling of the above exception, another exception occurred:

Traceback (most recent call last):
  File "watch.py", line 55, in watch
    raise Exception('dsads')
Exception: dsads

INFO:root:07/06/2023 18:52:06 - TGTG: 200(OK). Items: 79
INFO:root:07/06/2023 18:52:07 - Foodsi: 200(OK). Items with stock: 0 All items: 15
ERROR:root:Traceback (most recent call last):
  File "watch.py", line 55, in watch
    raise Exception('dsads')
Exception: dsads

During handling of the above exception, another exception occurred:

Traceback (most recent call last):
  File "watch.py", line 55, in watch
    raise Exception('dsads')
Exception: dsads

During handling of the above exception, another exception occurred:

Traceback (most recent call last):
  File "watch.py", line 55, in watch
    raise Exception('dsads')
Exception: dsads

During handling of the above exception, another exception occurred:

Traceback (most recent call last):
  File "watch.py", line 55, in watch
    raise Exception('dsads')
Exception: dsads

During handling of the above exception, another exception occurred:

Traceback (most recent call last):
  File "watch.py", line 55, in watch
    raise Exception('dsads')
Exception: dsads

INFO:root:07/06/2023 18:52:08 - TGTG: 200(OK). Items: 79
INFO:root:07/06/2023 18:52:10 - Foodsi: 200(OK). Items with stock: 0 All items: 15
ERROR:root:Traceback (most recent call last):
  File "watch.py", line 55, in watch
    raise Exception('dsads')
Exception: dsads

During handling of the above exception, another exception occurred:

Traceback (most recent call last):
  File "watch.py", line 55, in watch
    raise Exception('dsads')
Exception: dsads

During handling of the above exception, another exception occurred:

Traceback (most recent call last):
  File "watch.py", line 55, in watch
    raise Exception('dsads')
Exception: dsads

During handling of the above exception, another exception occurred:

Traceback (most recent call last):
  File "watch.py", line 55, in watch
    raise Exception('dsads')
Exception: dsads

During handling of the above exception, another exception occurred:

Traceback (most recent call last):
  File "watch.py", line 55, in watch
    raise Exception('dsads')
Exception: dsads

During handling of the above exception, another exception occurred:

Traceback (most recent call last):
  File "watch.py", line 55, in watch
    raise Exception('dsads')
Exception: dsads

INFO:root:07/06/2023 18:52:11 - TGTG: 200(OK). Items: 79
INFO:root:07/06/2023 18:52:12 - Foodsi: 200(OK). Items with stock: 0 All items: 15
ERROR:root:Traceback (most recent call last):
  File "watch.py", line 55, in watch
    raise Exception('dsads')
Exception: dsads

During handling of the above exception, another exception occurred:

Traceback (most recent call last):
  File "watch.py", line 55, in watch
    raise Exception('dsads')
Exception: dsads

During handling of the above exception, another exception occurred:

Traceback (most recent call last):
  File "watch.py", line 55, in watch
    raise Exception('dsads')
Exception: dsads

During handling of the above exception, another exception occurred:

Traceback (most recent call last):
  File "watch.py", line 55, in watch
    raise Exception('dsads')
Exception: dsads

During handling of the above exception, another exception occurred:

Traceback (most recent call last):
  File "watch.py", line 55, in watch
    raise Exception('dsads')
Exception: dsads

During handling of the above exception, another exception occurred:

Traceback (most recent call last):
  File "watch.py", line 55, in watch
    raise Exception('dsads')
Exception: dsads

During handling of the above exception, another exception occurred:

Traceback (most recent call last):
  File "watch.py", line 55, in watch
    raise Exception('dsads')
Exception: dsads

INFO:root:07/06/2023 18:52:13 - TGTG: 200(OK). Items: 79
INFO:root:07/06/2023 18:52:14 - Foodsi: 200(OK). Items with stock: 0 All items: 15
ERROR:root:Traceback (most recent call last):
  File "watch.py", line 55, in watch
    raise Exception('dsads')
Exception: dsads

During handling of the above exception, another exception occurred:

Traceback (most recent call last):
  File "watch.py", line 55, in watch
    raise Exception('dsads')
Exception: dsads

During handling of the above exception, another exception occurred:

Traceback (most recent call last):
  File "watch.py", line 55, in watch
    raise Exception('dsads')
Exception: dsads

During handling of the above exception, another exception occurred:

Traceback (most recent call last):
  File "watch.py", line 55, in watch
    raise Exception('dsads')
Exception: dsads

During handling of the above exception, another exception occurred:

Traceback (most recent call last):
  File "watch.py", line 55, in watch
    raise Exception('dsads')
Exception: dsads

During handling of the above exception, another exception occurred:

Traceback (most recent call last):
  File "watch.py", line 55, in watch
    raise Exception('dsads')
Exception: dsads

During handling of the above exception, another exception occurred:

Traceback (most recent call last):
  File "watch.py", line 55, in watch
    raise Exception('dsads')
Exception: dsads

During handling of the above exception, another exception occurred:

Traceback (most recent call last):
  File "watch.py", line 55, in watch
    raise Exception('dsads')
Exception: dsads

INFO:root:07/06/2023 18:52:15 - TGTG: 200(OK). Items: 79
INFO:root:07/06/2023 18:52:16 - Foodsi: 200(OK). Items with stock: 0 All items: 15
INFO:root:07/06/2023 18:52:58 - TGTG: 200(OK). Items: 79
INFO:root:07/06/2023 18:52:58 - Foodsi: 200(OK). Items with stock: 0 All items: 15
INFO:root:07/06/2023 18:53:40 - TGTG: 200(OK). Items: 79
INFO:root:07/06/2023 18:53:42 - Foodsi: 200(OK). Items with stock: 0 All items: 15
